2023-11-30 07:38:11,735 INFO    StreamThr :4999 [internal.py:wandb_internal():86] W&B internal server running at pid: 4999, started at: 2023-11-30 07:38:11.733201
2023-11-30 07:38:11,736 DEBUG   HandlerThread:4999 [handler.py:handle_request():144] handle_request: status
2023-11-30 07:38:11,741 INFO    WriterThread:4999 [datastore.py:open_for_write():85] open: /mnt/e/Personal/UC Davis/Research/Ilias/AIFS Projects/diet_recommendation/meal_recommender/wandb/run-20231130_073811-dxxyx7po/run-dxxyx7po.wandb
2023-11-30 07:38:11,743 DEBUG   SenderThread:4999 [sender.py:send():380] send: header
2023-11-30 07:38:11,798 DEBUG   SenderThread:4999 [sender.py:send():380] send: run
2023-11-30 07:38:14,505 ERROR   SenderThread:4999 [internal_api.py:execute():369] 400 response executing GraphQL.
2023-11-30 07:38:14,506 ERROR   SenderThread:4999 [internal_api.py:execute():370] {"errors":[{"message":"invalid tag ''. must be between 1 and 64 characters","path":["upsertBucket"]}],"data":{"upsertBucket":null}}
2023-11-30 07:38:14,506 ERROR   SenderThread:4999 [sender.py:send_run():977] invalid tag ''. must be between 1 and 64 characters (Error 400: Bad Request)
Traceback (most recent call last):
  File "/home/unixftwx/anaconda3/envs/drp/lib/python3.10/site-packages/wandb/apis/normalize.py", line 41, in wrapper
    return func(*args, **kwargs)
  File "/home/unixftwx/anaconda3/envs/drp/lib/python3.10/site-packages/wandb/sdk/internal/internal_api.py", line 2007, in upsert_run
    response = self.gql(
  File "/home/unixftwx/anaconda3/envs/drp/lib/python3.10/site-packages/wandb/sdk/internal/internal_api.py", line 338, in gql
    ret = self._retry_gql(
  File "/home/unixftwx/anaconda3/envs/drp/lib/python3.10/site-packages/wandb/sdk/lib/retry.py", line 131, in __call__
    result = self._call_fn(*args, **kwargs)
  File "/home/unixftwx/anaconda3/envs/drp/lib/python3.10/site-packages/wandb/sdk/internal/internal_api.py", line 366, in execute
    return self.client.execute(*args, **kwargs)  # type: ignore
  File "/home/unixftwx/anaconda3/envs/drp/lib/python3.10/site-packages/wandb/vendor/gql-0.2.0/wandb_gql/client.py", line 52, in execute
    result = self._get_result(document, *args, **kwargs)
  File "/home/unixftwx/anaconda3/envs/drp/lib/python3.10/site-packages/wandb/vendor/gql-0.2.0/wandb_gql/client.py", line 60, in _get_result
    return self.transport.execute(document, *args, **kwargs)
  File "/home/unixftwx/anaconda3/envs/drp/lib/python3.10/site-packages/wandb/sdk/lib/gql_request.py", line 59, in execute
    request.raise_for_status()
  File "/home/unixftwx/anaconda3/envs/drp/lib/python3.10/site-packages/requests/models.py", line 1021, in raise_for_status
    raise HTTPError(http_error_msg, response=self)
requests.exceptions.HTTPError: 400 Client Error: Bad Request for url: https://api.wandb.ai/graphql

During handling of the above exception, another exception occurred:

Traceback (most recent call last):
  File "/home/unixftwx/anaconda3/envs/drp/lib/python3.10/site-packages/wandb/sdk/internal/sender.py", line 975, in send_run
    self._init_run(run, config_value_dict)
  File "/home/unixftwx/anaconda3/envs/drp/lib/python3.10/site-packages/wandb/sdk/internal/sender.py", line 1013, in _init_run
    server_run, inserted, server_messages = self._api.upsert_run(
  File "/home/unixftwx/anaconda3/envs/drp/lib/python3.10/site-packages/wandb/apis/normalize.py", line 51, in wrapper
    raise CommError(message, error)
wandb.errors.CommError: invalid tag ''. must be between 1 and 64 characters (Error 400: Bad Request)
2023-11-30 07:38:14,905 DEBUG   HandlerThread:4999 [handler.py:handle_request():144] handle_request: shutdown
2023-11-30 07:38:14,905 INFO    HandlerThread:4999 [handler.py:finish():844] shutting down handler
2023-11-30 07:38:15,513 INFO    SenderThread:4999 [sender.py:finish():1534] shutting down sender
2023-11-30 07:38:15,799 INFO    WriterThread:4999 [datastore.py:close():294] close: /mnt/e/Personal/UC Davis/Research/Ilias/AIFS Projects/diet_recommendation/meal_recommender/wandb/run-20231130_073811-dxxyx7po/run-dxxyx7po.wandb
